<mujoco model="humanoid_legged_description">
  <compiler angle="radian" meshdir="../meshes/" />
  <size njmax="500" nconmax="100" />
  <option timestep="0.001" iterations="50" solver="PGS" gravity="0 0 -9.81" noslip_iterations="20">
  </option>
  <default>
    <joint limited="true" damping="0.01" armature="0.01" frictionloss="0.01" />
    <geom condim="4" contype="1" conaffinity="15" friction="0.9 0.2 0.2" solref="0.001 2" />
    <motor ctrllimited="true" />
    <equality solref="0.001 2" />
    <default class="visualgeom">
      <geom material="visualgeom" condim="1" contype="0" conaffinity="0" />
    </default>
  </default>


  <asset>
    <mesh name="LINK_BASE" file="LINK_BASE.STL" />
    <mesh name="LINK_R_BASE" file="LINK_R_BASE.STL" />
    <mesh name="LINK_R_HIP" file="LINK_R_HIP.STL" />
    <mesh name="LINK_R_THIGH" file="LINK_R_THIGH.STL" />
    <mesh name="LINK_R_SHANK" file="LINK_R_SHANK.STL" />
    <mesh name="LINK_R_ANK" file="LINK_R_ANK.STL" />
    <mesh name="LINK_R_FOOT" file="LINK_R_FOOT.STL" />
    <mesh name="LINK_RR_DPIN" file="LINK_RR_DPIN.STL" />
    <mesh name="LINK_RR_SCREW" file="LINK_RR_SCREW.STL" />
    <mesh name="LINK_RL_DPIN" file="LINK_RL_DPIN.STL" />
    <mesh name="LINK_RL_SCREW" file="LINK_RL_SCREW.STL" />
    <mesh name="LINK_RR_UPIN" file="LINK_RR_UPIN.STL" />
    <mesh name="LINK_RR_ACTU" file="LINK_RR_ACTU.STL" />
    <mesh name="LINK_RL_UPIN" file="LINK_RL_UPIN.STL" />
    <mesh name="LINK_RL_ACTU" file="LINK_RL_ACTU.STL" />
    <mesh name="LINK_R_ABD_ACTU" file="LINK_R_ABD_ACTU.STL" />
    <mesh name="LINK_L_BASE" file="LINK_L_BASE.STL" />
    <mesh name="LINK_L_HIP" file="LINK_L_HIP.STL" />
    <mesh name="LINK_L_THIGH" file="LINK_L_THIGH.STL" />
    <mesh name="LINK_L_SHANK" file="LINK_L_SHANK.STL" />
    <mesh name="LINK_L_ANK" file="LINK_L_ANK.STL" />
    <mesh name="LINK_L_FOOT" file="LINK_L_FOOT.STL" />
    <mesh name="LINK_LR_DPIN" file="LINK_LR_DPIN.STL" />
    <mesh name="LINK_LR_SCREW" file="LINK_LR_SCREW.STL" />
    <mesh name="LINK_LL_DPIN" file="LINK_LL_DPIN.STL" />
    <mesh name="LINK_LL_SCREW" file="LINK_LL_SCREW.STL" />
    <mesh name="LINK_LR_UPIN" file="LINK_LR_UPIN.STL" />
    <mesh name="LINK_LR_ACTU" file="LINK_LR_ACTU.STL" />
    <mesh name="LINK_LL_UPIN" file="LINK_LL_UPIN.STL" />
    <mesh name="LINK_LL_ACTU" file="LINK_LL_ACTU.STL" />
    <mesh name="LINK_L_ABD_ACTU" file="LINK_L_ABD_ACTU.STL" />
    <mesh name="LINK_R_ABD_SCREW" file="LINK_R_ABD_SCREW.STL" />
    <mesh name="LINK_L_ABD_SCREW" file="LINK_L_ABD_SCREW.STL" />
    <texture name="texplane" type="2d" builtin="checker" rgb1=".0 .0 .0" rgb2=".8 .8 .8" width="100" height="100" />
    <material name="matplane" reflectance="0." texture="texplane" texrepeat="1 1" texuniform="true" />
    <material name="visualgeom" rgba="0.5 0.9 0.2 1" />
  </asset>

  <worldbody>
    <light directional="true" diffuse="0.4 0.4 0.4" specular="0.1 0.1 0.1" pos="0 0 5.0" dir="0 0 -1" castshadow="false" />
    <light directional="true" diffuse="0.6 0.6 0.6" specular="0.2 0.2 0.2" pos="0 0 4" dir="0 0 -1" />
    <geom name="ground" type="plane" pos="0 0 0" size="100 100 0.001" quat="1 0 0 0" material="matplane" condim="3" conaffinity="15" />
    <camera name="fixed" pos="0 -3.0 1.7794628070965992" xyaxes="1 0 0 0 0 1" />
    <camera name="track" mode="trackcom" pos="0 -3.0 1.7794628070965992" xyaxes="1 0 0 0 0 1" />
    <body name="root" pos="0 0 1.2794628070965992" quat="1 0 0 0">
      <freejoint name="root" />
      <site name="imu" size="0.01" pos="0 0 0" />
      <geom type="mesh" contype="1" conaffinity="0" group="1" density="0" rgba="0.75294 0.75294 0.75294 1" mesh="LINK_BASE" class="visualgeom" />
      <geom type="mesh" rgba="0.75294 0.75294 0.75294 1" mesh="LINK_BASE" />
      <geom type="mesh" rgba="0.75294 0.75294 0.75294 1" mesh="LINK_BASE" contype="1" conaffinity="0" density="0" group="1" class="visualgeom" />
      <geom type="mesh" rgba="0.75294 0.75294 0.75294 1" mesh="LINK_BASE" />
      <geom pos="-0.027 -0.173 0.106" quat="1 0 0 0" type="mesh" contype="1" conaffinity="0" group="1" density="0" rgba="0.75294 0.75294 0.75294 1" mesh="LINK_R_ABD_SCREW" class="visualgeom" />
      <geom type="mesh" rgba="0.75294 0.75294 0.75294 1" mesh="LINK_R_ABD_SCREW" pos="-0.027 -0.173 0.106" quat="1 0 0 0" />
      <geom pos="-0.027 -0.173 0.106" quat="1 0 0 0" type="mesh" rgba="0.75294 0.75294 0.75294 1" mesh="LINK_R_ABD_SCREW" contype="1" conaffinity="0" density="0" group="1" class="visualgeom" />
      <geom type="mesh" rgba="0.75294 0.75294 0.75294 1" mesh="LINK_R_ABD_SCREW" pos="-0.027 -0.173 0.106" quat="1 0 0 0" />
      <geom pos="-0.027 0.173 0.106" quat="1 0 0 0" type="mesh" contype="1" conaffinity="0" group="1" density="0" rgba="0.75294 0.75294 0.75294 1" mesh="LINK_L_ABD_SCREW" class="visualgeom" />
      <geom type="mesh" rgba="0.75294 0.75294 0.75294 1" mesh="LINK_L_ABD_SCREW" pos="-0.027 0.173 0.106" quat="1 0 0 0" />
      <geom pos="-0.027 0.173 0.106" quat="1 0 0 0" type="mesh" rgba="0.75294 0.75294 0.75294 1" mesh="LINK_L_ABD_SCREW" contype="1" conaffinity="0" density="0" group="1" class="visualgeom" />
      <geom type="mesh" rgba="0.75294 0.75294 0.75294 1" mesh="LINK_L_ABD_SCREW" pos="-0.027 0.173 0.106" quat="1 0 0 0" />
      <body name="LINK_R_BASE" pos="0 -0.105 0">
        <inertial pos="-0.11287 -0.126052 0.000425645" quat="0.202865 0.580849 0.0648717 0.785654" mass="4.46389" diaginertia="0.0204357 0.0183075 0.00405648" />
        <joint name="leg_r1_joint" pos="0 0 0" axis="-1 0 0" range="-0.17453 0.2618" />
        <geom type="mesh" contype="1" conaffinity="0" group="1" density="0" rgba="0.75294 0.75294 0.75294 1" mesh="LINK_R_BASE" class="visualgeom" />
        <geom type="mesh" rgba="0.75294 0.75294 0.75294 1" mesh="LINK_R_BASE" />
        <geom type="mesh" rgba="0.75294 0.75294 0.75294 1" mesh="LINK_R_BASE" contype="1" conaffinity="0" density="0" group="1" class="visualgeom" />
        <geom type="mesh" rgba="0.75294 0.75294 0.75294 1" mesh="LINK_R_BASE" />
        <geom pos="-0.089 -0.10864 0.05722" quat="1 0 0 0" type="mesh" contype="1" conaffinity="0" group="1" density="0" rgba="0.75294 0.75294 0.75294 1" mesh="LINK_R_ABD_ACTU" class="visualgeom" />
        <geom type="mesh" rgba="0.75294 0.75294 0.75294 1" mesh="LINK_R_ABD_ACTU" pos="-0.089 -0.10864 0.05722" quat="1 0 0 0" />
        <geom pos="-0.089 -0.10864 0.05722" quat="1 0 0 0" type="mesh" rgba="0.75294 0.75294 0.75294 1" mesh="LINK_R_ABD_ACTU" contype="1" conaffinity="0" density="0" group="1" class="visualgeom" />
        <geom type="mesh" rgba="0.75294 0.75294 0.75294 1" mesh="LINK_R_ABD_ACTU" pos="-0.089 -0.10864 0.05722" quat="1 0 0 0" />
        <body name="LINK_R_HIP" pos="-0.246 -0.155 0.0018" quat="9.38184e-07 0.707105 9.38187e-07 -0.707108">
          <inertial pos="0.1573 0.00247 0.00753" quat="0.272996 0.657178 0.649267 0.268407" mass="3.93858" diaginertia="0.00711053 0.00440983 0.00366964" />
          <joint name="leg_r2_joint" pos="0 0 0" axis="1 0 0" range="-0.2618 0.2618" />
          <geom type="mesh" contype="1" conaffinity="0" group="1" density="0" rgba="0.75294 0.75294 0.75294 1" mesh="LINK_R_HIP" class="visualgeom" />
          <geom type="mesh" rgba="0.75294 0.75294 0.75294 1" mesh="LINK_R_HIP" />
          <geom type="mesh" rgba="0.75294 0.75294 0.75294 1" mesh="LINK_R_HIP" contype="1" conaffinity="0" density="0" group="1" class="visualgeom" />
          <geom type="mesh" rgba="0.75294 0.75294 0.75294 1" mesh="LINK_R_HIP" />
          <body name="LINK_R_THIGH" pos="0.1908 0.036 0" quat="9.38184e-07 -0.707105 0.707108 -9.38187e-07">
            <inertial pos="0.02583 -0.24821 -0.00792" quat="0.706684 0.706975 0.0167916 0.0224208" mass="3.57819" diaginertia="0.00723285 0.00597992 0.00307723" />
            <joint name="leg_r3_joint" pos="0 0 0" axis="-1 0 0" range="-0.5236 1.884" />
            <geom type="mesh" contype="1" conaffinity="0" group="1" density="0" rgba="0.75294 0.75294 0.75294 1" mesh="LINK_R_THIGH" class="visualgeom" />
            <geom type="mesh" rgba="0.75294 0.75294 0.75294 1" mesh="LINK_R_THIGH" />
            <geom type="mesh" rgba="0.75294 0.75294 0.75294 1" mesh="LINK_R_THIGH" contype="1" conaffinity="0" density="0" group="1" class="visualgeom" />
            <geom type="mesh" rgba="0.75294 0.75294 0.75294 1" mesh="LINK_R_THIGH" />
            <body name="LINK_R_SHANK" pos="0.02624 -0.43062 -0.009">
              <inertial pos="0.134324 -0.152976 0.127213" quat="0.502075 0.423933 -0.296722 0.692934" mass="5.26285" diaginertia="0.0307194 0.0234929 0.0143883" />
              <joint name="leg_r4_joint" pos="0 0 0" axis="1 0 0" range="0.004 2.0944" />
              <geom type="mesh" contype="1" conaffinity="0" group="1" density="0" rgba="0.75294 0.75294 0.75294 1" mesh="LINK_R_SHANK" class="visualgeom" />
              <geom type="mesh" rgba="0.75294 0.75294 0.75294 1" mesh="LINK_R_SHANK" />
              <geom type="mesh" rgba="0.75294 0.75294 0.75294 1" mesh="LINK_R_SHANK" contype="1" conaffinity="0" density="0" group="1" class="visualgeom" />
              <geom type="mesh" rgba="0.75294 0.75294 0.75294 1" mesh="LINK_R_SHANK" />
              <geom pos="0.086 -0.14659 0.10362" quat="0.572131 -0.820163 0 0" type="mesh" contype="1" conaffinity="0" group="1" density="0" rgba="0.65098 0.61961 0.58824 1" mesh="LINK_RR_UPIN" class="visualgeom" />
              <geom type="mesh" rgba="0.65098 0.61961 0.58824 1" mesh="LINK_RR_UPIN" pos="0.086 -0.14659 0.10362" quat="0.572131 -0.820163 0 0" />
              <geom pos="0.086 -0.14659 0.10362" quat="0.572131 -0.820163 0 0" type="mesh" rgba="0.65098 0.61961 0.58824 1" mesh="LINK_RR_UPIN" contype="1" conaffinity="0" density="0" group="1" class="visualgeom" />
              <geom type="mesh" rgba="0.65098 0.61961 0.58824 1" mesh="LINK_RR_UPIN" pos="0.086 -0.14659 0.10362" quat="0.572131 -0.820163 0 0" />
              <geom pos="0.086 -0.14659 0.10362" quat="0.572131 -0.820163 0 0" type="mesh" contype="1" conaffinity="0" group="1" density="0" rgba="0.75294 0.75294 0.75294 1" mesh="LINK_RR_ACTU" class="visualgeom" />
              <geom type="mesh" rgba="0.75294 0.75294 0.75294 1" mesh="LINK_RR_ACTU" pos="0.086 -0.14659 0.10362" quat="0.572131 -0.820163 0 0" />
              <geom pos="0.086 -0.14659 0.10362" quat="0.572131 -0.820163 0 0" type="mesh" rgba="0.75294 0.75294 0.75294 1" mesh="LINK_RR_ACTU" contype="1" conaffinity="0" density="0" group="1" class="visualgeom" />
              <geom type="mesh" rgba="0.75294 0.75294 0.75294 1" mesh="LINK_RR_ACTU" pos="0.086 -0.14659 0.10362" quat="0.572131 -0.820163 0 0" />
              <geom pos="0.203 -0.14659 0.10362" quat="0.570325 -0.821419 0 0" type="mesh" contype="1" conaffinity="0" group="1" density="0" rgba="0.65098 0.61961 0.58824 1" mesh="LINK_RL_UPIN" class="visualgeom" />
              <geom type="mesh" rgba="0.65098 0.61961 0.58824 1" mesh="LINK_RL_UPIN" pos="0.203 -0.14659 0.10362" quat="0.570325 -0.821419 0 0" />
              <geom pos="0.203 -0.14659 0.10362" quat="0.570325 -0.821419 0 0" type="mesh" rgba="0.65098 0.61961 0.58824 1" mesh="LINK_RL_UPIN" contype="1" conaffinity="0" density="0" group="1" class="visualgeom" />
              <geom type="mesh" rgba="0.65098 0.61961 0.58824 1" mesh="LINK_RL_UPIN" pos="0.203 -0.14659 0.10362" quat="0.570325 -0.821419 0 0" />
              <geom pos="0.203 -0.14659 0.10362" quat="0.570325 -0.821419 0 0" type="mesh" contype="1" conaffinity="0" group="1" density="0" rgba="0.75294 0.75294 0.75294 1" mesh="LINK_RL_ACTU" class="visualgeom" />
              <geom type="mesh" rgba="0.75294 0.75294 0.75294 1" mesh="LINK_RL_ACTU" pos="0.203 -0.14659 0.10362" quat="0.570325 -0.821419 0 0" />
              <geom pos="0.203 -0.14659 0.10362" quat="0.570325 -0.821419 0 0" type="mesh" rgba="0.75294 0.75294 0.75294 1" mesh="LINK_RL_ACTU" contype="1" conaffinity="0" density="0" group="1" class="visualgeom" />
              <geom type="mesh" rgba="0.75294 0.75294 0.75294 1" mesh="LINK_RL_ACTU" pos="0.203 -0.14659 0.10362" quat="0.570325 -0.821419 0 0" />
              <body name="LINK_R_ANK" pos="0.1445 -0.29452 0.12171" quat="0.939693 -0.342019 0 0">
                <inertial pos="0 0.00012 -0.06408" quat="0.5 0.5 0.5 0.5" mass="0.55947" diaginertia="0.00286 0.00202 0.00102" />
                <joint name="leg_r6_joint" pos="0 0 0" axis="0 0 1" range="-0.1744 0.2618" />
                <geom type="mesh" contype="1" conaffinity="0" group="1" density="0" rgba="0.75294 0.75294 0.75294 1" mesh="LINK_R_ANK" class="visualgeom" />
                <geom type="mesh" rgba="0.75294 0.75294 0.75294 1" mesh="LINK_R_ANK" />
                <geom type="mesh" rgba="0.75294 0.75294 0.75294 1" mesh="LINK_R_ANK" contype="1" conaffinity="0" density="0" group="1" class="visualgeom" />
                <geom type="mesh" rgba="0.75294 0.75294 0.75294 1" mesh="LINK_R_ANK" />
                <body name="LINK_R_FOOT" pos="-0.0885 0 -0.148" quat="0.939693 0.342019 0 0">
                  <inertial pos="0.0863054 -0.0627131 0.106446" quat="0.390792 0.919942 -0.031425 0.000551532" mass="5.05404" diaginertia="0.0712285 0.0626161 0.0347242" />
                  <joint name="leg_r5_joint" pos="0 0 0" axis="1 0 0" range="-0.35 0.52" />
                  <geom type="mesh" contype="1" conaffinity="0" group="1" density="0" rgba="0.75294 0.75294 0.75294 1" mesh="LINK_R_FOOT" class="visualgeom" />
                  <geom type="mesh" rgba="0.75294 0.75294 0.75294 1" mesh="LINK_R_FOOT" />
                  <geom type="mesh" rgba="0.75294 0.75294 0.75294 1" mesh="LINK_R_FOOT" contype="1" conaffinity="0" density="0" group="1" class="visualgeom" />
                  <geom type="mesh" rgba="0.75294 0.75294 0.75294 1" mesh="LINK_R_FOOT" />
                  <geom pos="0.036 -0.014 0.2299" quat="0.571971 -0.820274 0 0" type="mesh" contype="1" conaffinity="0" group="1" density="0" rgba="0.65098 0.61961 0.58824 1" mesh="LINK_RR_DPIN" class="visualgeom" />
                  <geom type="mesh" rgba="0.65098 0.61961 0.58824 1" mesh="LINK_RR_DPIN" pos="0.036 -0.014 0.2299" quat="0.571971 -0.820274 0 0" />
                  <geom pos="0.036 -0.014 0.2299" quat="0.571971 -0.820274 0 0" type="mesh" rgba="0.65098 0.61961 0.58824 1" mesh="LINK_RR_DPIN" contype="1" conaffinity="0" density="0" group="1" class="visualgeom" />
                  <geom type="mesh" rgba="0.65098 0.61961 0.58824 1" mesh="LINK_RR_DPIN" pos="0.036 -0.014 0.2299" quat="0.571971 -0.820274 0 0" />
                  <geom pos="0.036 -0.014 0.2299" quat="0.571971 -0.820274 0 0" type="mesh" contype="1" conaffinity="0" group="1" density="0" rgba="0.75294 0.75294 0.75294 1" mesh="LINK_RR_SCREW" class="visualgeom" />
                  <geom type="mesh" rgba="0.75294 0.75294 0.75294 1" mesh="LINK_RR_SCREW" pos="0.036 -0.014 0.2299" quat="0.571971 -0.820274 0 0" />
                  <geom pos="0.036 -0.014 0.2299" quat="0.571971 -0.820274 0 0" type="mesh" rgba="0.75294 0.75294 0.75294 1" mesh="LINK_RR_SCREW" contype="1" conaffinity="0" density="0" group="1" class="visualgeom" />
                  <geom type="mesh" rgba="0.75294 0.75294 0.75294 1" mesh="LINK_RR_SCREW" pos="0.036 -0.014 0.2299" quat="0.571971 -0.820274 0 0" />
                  <geom pos="0.141 -0.014 0.2301" quat="0.569992 -0.82165 0 0" type="mesh" contype="1" conaffinity="0" group="1" density="0" rgba="0.65098 0.61961 0.58824 1" mesh="LINK_RL_DPIN" class="visualgeom" />
                  <geom type="mesh" rgba="0.65098 0.61961 0.58824 1" mesh="LINK_RL_DPIN" pos="0.141 -0.014 0.2301" quat="0.569992 -0.82165 0 0" />
                  <geom pos="0.141 -0.014 0.2301" quat="0.569992 -0.82165 0 0" type="mesh" rgba="0.65098 0.61961 0.58824 1" mesh="LINK_RL_DPIN" contype="1" conaffinity="0" density="0" group="1" class="visualgeom" />
                  <geom type="mesh" rgba="0.65098 0.61961 0.58824 1" mesh="LINK_RL_DPIN" pos="0.141 -0.014 0.2301" quat="0.569992 -0.82165 0 0" />
                  <geom pos="0.141 -0.014 0.2301" quat="0.569992 -0.82165 0 0" type="mesh" contype="1" conaffinity="0" group="1" density="0" rgba="0.75294 0.75294 0.75294 1" mesh="LINK_RL_SCREW" class="visualgeom" />
                  <geom type="mesh" rgba="0.75294 0.75294 0.75294 1" mesh="LINK_RL_SCREW" pos="0.141 -0.014 0.2301" quat="0.569992 -0.82165 0 0" />
                  <geom pos="0.141 -0.014 0.2301" quat="0.569992 -0.82165 0 0" type="mesh" rgba="0.75294 0.75294 0.75294 1" mesh="LINK_RL_SCREW" contype="1" conaffinity="0" density="0" group="1" class="visualgeom" />
                  <geom type="mesh" rgba="0.75294 0.75294 0.75294 1" mesh="LINK_RL_SCREW" pos="0.141 -0.014 0.2301" quat="0.569992 -0.82165 0 0" />
                </body>
              </body>
            </body>
          </body>
        </body>
      </body>
      <body name="LINK_L_BASE" pos="0 0.105 0">
        <inertial pos="-0.11302 0.1261 0.000347075" quat="-0.202312 0.581305 -0.0641563 0.785518" mass="4.45416" diaginertia="0.020393 0.0182576 0.00404802" />
        <joint name="leg_l1_joint" pos="0 0 0" axis="1 0 0" range="-0.17453 0.2618" />
        <geom type="mesh" contype="1" conaffinity="0" group="1" density="0" rgba="0.75294 0.75294 0.75294 1" mesh="LINK_L_BASE" class="visualgeom" />
        <geom type="mesh" rgba="0.75294 0.75294 0.75294 1" mesh="LINK_L_BASE" />
        <geom type="mesh" rgba="0.75294 0.75294 0.75294 1" mesh="LINK_L_BASE" contype="1" conaffinity="0" density="0" group="1" class="visualgeom" />
        <geom type="mesh" rgba="0.75294 0.75294 0.75294 1" mesh="LINK_L_BASE" />
        <geom pos="-0.089 0.109 0.057" quat="1 0 0 0" type="mesh" contype="1" conaffinity="0" group="1" density="0" rgba="0.75294 0.75294 0.75294 1" mesh="LINK_L_ABD_ACTU" class="visualgeom" />
        <geom type="mesh" rgba="0.75294 0.75294 0.75294 1" mesh="LINK_L_ABD_ACTU" pos="-0.089 0.109 0.057" quat="1 0 0 0" />
        <geom pos="-0.089 0.109 0.057" quat="1 0 0 0" type="mesh" rgba="0.75294 0.75294 0.75294 1" mesh="LINK_L_ABD_ACTU" contype="1" conaffinity="0" density="0" group="1" class="visualgeom" />
        <geom type="mesh" rgba="0.75294 0.75294 0.75294 1" mesh="LINK_L_ABD_ACTU" pos="-0.089 0.109 0.057" quat="1 0 0 0" />
        <body name="LINK_L_HIP" pos="-0.246 0.155 0.0018" quat="9.38184e-07 0.707105 9.38187e-07 -0.707108">
          <inertial pos="0.1573 -0.00269 0.00753" quat="0.268407 0.649267 0.657178 0.272996" mass="3.93858" diaginertia="0.00711053 0.00440983 0.00366964" />
          <joint name="leg_l2_joint" pos="0 0 0" axis="-1 0 0" range="-0.2618 0.2618" />
          <geom type="mesh" contype="1" conaffinity="0" group="1" density="0" rgba="0.75294 0.75294 0.75294 1" mesh="LINK_L_HIP" class="visualgeom" />
          <geom type="mesh" rgba="0.75294 0.75294 0.75294 1" mesh="LINK_L_HIP" />
          <geom type="mesh" rgba="0.75294 0.75294 0.75294 1" mesh="LINK_L_HIP" contype="1" conaffinity="0" density="0" group="1" class="visualgeom" />
          <geom type="mesh" rgba="0.75294 0.75294 0.75294 1" mesh="LINK_L_HIP" />
          <body name="LINK_L_THIGH" pos="0.1908 -0.036 0" quat="9.38184e-07 -0.707105 0.707108 -9.38187e-07">
            <inertial pos="-0.0215 -0.2549 -0.00789" quat="0.706695 0.707 -0.0160681 -0.0217987" mass="3.04454" diaginertia="0.0066008 0.00536992 0.00285928" />
            <joint name="leg_l3_joint" pos="0 0 0" axis="-1 0 0" range="-0.5236 1.884" />
            <geom type="mesh" contype="1" conaffinity="0" group="1" density="0" rgba="0.75294 0.75294 0.75294 1" mesh="LINK_L_THIGH" class="visualgeom" />
            <geom type="mesh" rgba="0.75294 0.75294 0.75294 1" mesh="LINK_L_THIGH" />
            <geom type="mesh" rgba="0.75294 0.75294 0.75294 1" mesh="LINK_L_THIGH" contype="1" conaffinity="0" density="0" group="1" class="visualgeom" />
            <geom type="mesh" rgba="0.75294 0.75294 0.75294 1" mesh="LINK_L_THIGH" />
            <body name="LINK_L_SHANK" pos="-0.02624 -0.43062 -0.009">
              <inertial pos="-0.134806 -0.153131 0.127363" quat="0.695784 0.290932 -0.429163 0.497054" mass="5.23094" diaginertia="0.0307491 0.023579 0.0143222" />
              <joint name="leg_l4_joint" pos="0 0 0" axis="1 0 0" range="0.004 2.0944" />
              <geom type="mesh" contype="1" conaffinity="0" group="1" density="0" rgba="0.75294 0.75294 0.75294 1" mesh="LINK_L_SHANK" class="visualgeom" />
              <geom type="mesh" rgba="0.75294 0.75294 0.75294 1" mesh="LINK_L_SHANK" />
              <geom type="mesh" rgba="0.75294 0.75294 0.75294 1" mesh="LINK_L_SHANK" contype="1" conaffinity="0" density="0" group="1" class="visualgeom" />
              <geom type="mesh" rgba="0.75294 0.75294 0.75294 1" mesh="LINK_L_SHANK" />
              <geom pos="-0.203 -0.14659 0.10362" quat="0.820726 0.571321 0 0" type="mesh" contype="1" conaffinity="0" group="1" density="0" rgba="0.65098 0.61961 0.58824 1" mesh="LINK_LR_UPIN" class="visualgeom" />
              <geom type="mesh" rgba="0.65098 0.61961 0.58824 1" mesh="LINK_LR_UPIN" pos="-0.203 -0.14659 0.10362" quat="0.820726 0.571321 0 0" />
              <geom pos="-0.203 -0.14659 0.10362" quat="0.820726 0.571321 0 0" type="mesh" rgba="0.65098 0.61961 0.58824 1" mesh="LINK_LR_UPIN" contype="1" conaffinity="0" density="0" group="1" class="visualgeom" />
              <geom type="mesh" rgba="0.65098 0.61961 0.58824 1" mesh="LINK_LR_UPIN" pos="-0.203 -0.14659 0.10362" quat="0.820726 0.571321 0 0" />
              <geom pos="-0.203 -0.14659 0.10362" quat="0.820726 0.571321 0 0" type="mesh" contype="1" conaffinity="0" group="1" density="0" rgba="0.75294 0.75294 0.75294 1" mesh="LINK_LR_ACTU" class="visualgeom" />
              <geom type="mesh" rgba="0.75294 0.75294 0.75294 1" mesh="LINK_LR_ACTU" pos="-0.203 -0.14659 0.10362" quat="0.820726 0.571321 0 0" />
              <geom pos="-0.203 -0.14659 0.10362" quat="0.820726 0.571321 0 0" type="mesh" rgba="0.75294 0.75294 0.75294 1" mesh="LINK_LR_ACTU" contype="1" conaffinity="0" density="0" group="1" class="visualgeom" />
              <geom type="mesh" rgba="0.75294 0.75294 0.75294 1" mesh="LINK_LR_ACTU" pos="-0.203 -0.14659 0.10362" quat="0.820726 0.571321 0 0" />
              <geom pos="-0.086 -0.14659 0.10362" quat="0.820912 0.571055 0 0" type="mesh" contype="1" conaffinity="0" group="1" density="0" rgba="0.65098 0.61961 0.58824 1" mesh="LINK_LL_UPIN" class="visualgeom" />
              <geom type="mesh" rgba="0.65098 0.61961 0.58824 1" mesh="LINK_LL_UPIN" pos="-0.086 -0.14659 0.10362" quat="0.820912 0.571055 0 0" />
              <geom pos="-0.086 -0.14659 0.10362" quat="0.820912 0.571055 0 0" type="mesh" rgba="0.65098 0.61961 0.58824 1" mesh="LINK_LL_UPIN" contype="1" conaffinity="0" density="0" group="1" class="visualgeom" />
              <geom type="mesh" rgba="0.65098 0.61961 0.58824 1" mesh="LINK_LL_UPIN" pos="-0.086 -0.14659 0.10362" quat="0.820912 0.571055 0 0" />
              <geom pos="-0.086 -0.14659 0.10362" quat="0.820912 0.571055 0 0" type="mesh" contype="1" conaffinity="0" group="1" density="0" rgba="0.75294 0.75294 0.75294 1" mesh="LINK_LL_ACTU" class="visualgeom" />
              <geom type="mesh" rgba="0.75294 0.75294 0.75294 1" mesh="LINK_LL_ACTU" pos="-0.086 -0.14659 0.10362" quat="0.820912 0.571055 0 0" />
              <geom pos="-0.086 -0.14659 0.10362" quat="0.820912 0.571055 0 0" type="mesh" rgba="0.75294 0.75294 0.75294 1" mesh="LINK_LL_ACTU" contype="1" conaffinity="0" density="0" group="1" class="visualgeom" />
              <geom type="mesh" rgba="0.75294 0.75294 0.75294 1" mesh="LINK_LL_ACTU" pos="-0.086 -0.14659 0.10362" quat="0.820912 0.571055 0 0" />
              <body name="LINK_L_ANK" pos="-0.1445 -0.29452 0.12171" quat="0.939693 -0.342019 0 0">
                <inertial pos="0 0.00012 -0.06408" quat="0.5 0.5 0.5 0.5" mass="0.55947" diaginertia="0.00286 0.00202 0.00102" />
                <joint name="leg_l6_joint" pos="0 0 0" axis="0 0 -1" range="-0.1744 0.2618" />
                <geom type="mesh" contype="1" conaffinity="0" group="1" density="0" rgba="0.75294 0.75294 0.75294 1" mesh="LINK_L_ANK" class="visualgeom" />
                <geom type="mesh" rgba="0.75294 0.75294 0.75294 1" mesh="LINK_L_ANK" />
                <geom type="mesh" rgba="0.75294 0.75294 0.75294 1" mesh="LINK_L_ANK" contype="1" conaffinity="0" density="0" group="1" class="visualgeom" />
                <geom type="mesh" rgba="0.75294 0.75294 0.75294 1" mesh="LINK_L_ANK" />
                <body name="LINK_L_FOOT" pos="0.0885 0 -0.148" quat="0.939693 0.342019 0 0">
                  <inertial pos="-0.0860161 -0.0602319 0.106347" quat="0.393008 0.919305 0.020524 -0.00145385" mass="4.96548" diaginertia="0.0693148 0.0612127 0.0335976" />
                  <joint name="leg_l5_joint" pos="0 0 0" axis="1 0 0" range="-0.35 0.52" />
                  <geom type="mesh" contype="1" conaffinity="0" group="1" density="0" rgba="0.75294 0.75294 0.75294 1" mesh="LINK_L_FOOT" class="visualgeom" />
                  <geom type="mesh" rgba="0.75294 0.75294 0.75294 1" mesh="LINK_L_FOOT" />
                  <geom type="mesh" rgba="0.75294 0.75294 0.75294 1" mesh="LINK_L_FOOT" contype="1" conaffinity="0" density="0" group="1" class="visualgeom" />
                  <geom type="mesh" rgba="0.75294 0.75294 0.75294 1" mesh="LINK_L_FOOT" />
                  <geom pos="-0.141 -0.014 0.2299" quat="0.571322 -0.820726 0 0" type="mesh" contype="1" conaffinity="0" group="1" density="0" rgba="0.65098 0.61961 0.58824 1" mesh="LINK_LR_DPIN" class="visualgeom" />
                  <geom type="mesh" rgba="0.65098 0.61961 0.58824 1" mesh="LINK_LR_DPIN" pos="-0.141 -0.014 0.2299" quat="0.571322 -0.820726 0 0" />
                  <geom pos="-0.141 -0.014 0.2299" quat="0.571322 -0.820726 0 0" type="mesh" rgba="0.65098 0.61961 0.58824 1" mesh="LINK_LR_DPIN" contype="1" conaffinity="0" density="0" group="1" class="visualgeom" />
                  <geom type="mesh" rgba="0.65098 0.61961 0.58824 1" mesh="LINK_LR_DPIN" pos="-0.141 -0.014 0.2299" quat="0.571322 -0.820726 0 0" />
                  <geom pos="-0.141 -0.014 0.2299" quat="0.571322 -0.820726 0 0" type="mesh" contype="1" conaffinity="0" group="1" density="0" rgba="0.75294 0.75294 0.75294 1" mesh="LINK_LR_SCREW" class="visualgeom" />
                  <geom type="mesh" rgba="0.75294 0.75294 0.75294 1" mesh="LINK_LR_SCREW" pos="-0.141 -0.014 0.2299" quat="0.571322 -0.820726 0 0" />
                  <geom pos="-0.141 -0.014 0.2299" quat="0.571322 -0.820726 0 0" type="mesh" rgba="0.75294 0.75294 0.75294 1" mesh="LINK_LR_SCREW" contype="1" conaffinity="0" density="0" group="1" class="visualgeom" />
                  <geom type="mesh" rgba="0.75294 0.75294 0.75294 1" mesh="LINK_LR_SCREW" pos="-0.141 -0.014 0.2299" quat="0.571322 -0.820726 0 0" />
                  <geom pos="-0.036 -0.014 0.2301" quat="0.571056 -0.820911 0 0" type="mesh" contype="1" conaffinity="0" group="1" density="0" rgba="0.65098 0.61961 0.58824 1" mesh="LINK_LL_DPIN" class="visualgeom" />
                  <geom type="mesh" rgba="0.65098 0.61961 0.58824 1" mesh="LINK_LL_DPIN" pos="-0.036 -0.014 0.2301" quat="0.571056 -0.820911 0 0" />
                  <geom pos="-0.036 -0.014 0.2301" quat="0.571056 -0.820911 0 0" type="mesh" rgba="0.65098 0.61961 0.58824 1" mesh="LINK_LL_DPIN" contype="1" conaffinity="0" density="0" group="1" class="visualgeom" />
                  <geom type="mesh" rgba="0.65098 0.61961 0.58824 1" mesh="LINK_LL_DPIN" pos="-0.036 -0.014 0.2301" quat="0.571056 -0.820911 0 0" />
                  <geom pos="-0.036 -0.014 0.2301" quat="0.571056 -0.820911 0 0" type="mesh" contype="1" conaffinity="0" group="1" density="0" rgba="0.75294 0.75294 0.75294 1" mesh="LINK_LL_SCREW" class="visualgeom" />
                  <geom type="mesh" rgba="0.75294 0.75294 0.75294 1" mesh="LINK_LL_SCREW" pos="-0.036 -0.014 0.2301" quat="0.571056 -0.820911 0 0" />
                  <geom pos="-0.036 -0.014 0.2301" quat="0.571056 -0.820911 0 0" type="mesh" rgba="0.75294 0.75294 0.75294 1" mesh="LINK_LL_SCREW" contype="1" conaffinity="0" density="0" group="1" class="visualgeom" />
                  <geom type="mesh" rgba="0.75294 0.75294 0.75294 1" mesh="LINK_LL_SCREW" pos="-0.036 -0.014 0.2301" quat="0.571056 -0.820911 0 0" />
                </body>
              </body>
            </body>
          </body>
        </body>
      </body>
    </body>
  </worldbody>

    <contact>
      <exclude name="self_collision1" body1="LINK_L_SHANK" body2="LINK_L_FOOT" />
      <exclude name="self_collision2" body1="LINK_R_SHANK" body2="LINK_R_FOOT" />
  </contact>

  <actuator>
        <motor gear="1" joint="leg_l1_joint" name="leg_l1_motor" ctrllimited="true"  ctrlrange='-150 150'/>
        <motor gear="1" joint="leg_l2_joint" name="leg_l2_motor" ctrllimited="true"  ctrlrange='-150 150'/>
        <motor gear="1" joint="leg_l3_joint" name="leg_l3_motor" ctrllimited="true"  ctrlrange='-200 200'/>
        <motor gear="1" joint="leg_l4_joint" name="leg_l4_motor" ctrllimited="true"  ctrlrange='-200 200'/>
        <motor gear="1" joint="leg_l5_joint" name="leg_l5_motor" ctrllimited="true"  ctrlrange='-90 90'/>
        <motor gear="1" joint="leg_l6_joint" name="leg_l6_motor" ctrllimited="true"  ctrlrange='-90 90'/>
        <motor gear="1" joint="leg_r1_joint" name="leg_r1_motor" ctrllimited="true"  ctrlrange='-150 150'/>
        <motor gear="1" joint="leg_r2_joint" name="leg_r2_motor" ctrllimited="true"  ctrlrange='-150 150'/>
        <motor gear="1" joint="leg_r3_joint" name="leg_r3_motor" ctrllimited="true"  ctrlrange='-200 200'/>
        <motor gear="1" joint="leg_r4_joint" name="leg_r4_motor" ctrllimited="true"  ctrlrange='-200 200'/>
        <motor gear="1" joint="leg_r5_joint" name="leg_r5_motor" ctrllimited="true"  ctrlrange='-90 90'/>
        <motor gear="1" joint="leg_r6_joint" name="leg_r6_motor" ctrllimited="true"  ctrlrange='-90 90'/>
    </actuator>
    <sensor>
        <jointpos name="leg_l1_pos" joint="leg_l1_joint"/>
        <jointpos name="leg_l2_pos" joint="leg_l2_joint"/>
        <jointpos name="leg_l3_pos" joint="leg_l3_joint"/>
        <jointpos name="leg_l4_pos" joint="leg_l4_joint"/>
        <jointpos name="leg_l5_pos" joint="leg_l5_joint"/>
        <jointpos name="leg_l6_pos" joint="leg_l6_joint"/>
        <jointpos name="leg_r1_pos" joint="leg_r1_joint"/>
        <jointpos name="leg_r2_pos" joint="leg_r2_joint"/>
        <jointpos name="leg_r3_pos" joint="leg_r3_joint"/>
        <jointpos name="leg_r4_pos" joint="leg_r4_joint"/>
        <jointpos name="leg_r5_pos" joint="leg_r5_joint"/>
        <jointpos name="leg_r6_pos" joint="leg_r6_joint"/>
        <jointvel name="leg_l1_vel" joint="leg_l1_joint"/>
        <jointvel name="leg_l2_vel" joint="leg_l2_joint"/>
        <jointvel name="leg_l3_vel" joint="leg_l3_joint"/>
        <jointvel name="leg_l4_vel" joint="leg_l4_joint"/>
        <jointvel name="leg_l5_vel" joint="leg_l5_joint"/>
        <jointvel name="leg_l6_vel" joint="leg_l6_joint"/>
        <jointvel name="leg_r1_vel" joint="leg_r1_joint"/>
        <jointvel name="leg_r2_vel" joint="leg_r2_joint"/>
        <jointvel name="leg_r3_vel" joint="leg_r3_joint"/>
        <jointvel name="leg_r4_vel" joint="leg_r4_joint"/>
        <jointvel name="leg_r5_vel" joint="leg_r5_joint"/>
        <jointvel name="leg_r6_vel" joint="leg_r6_joint"/>
        <accelerometer name="BodyAcc" site="imu"/>
        <velocimeter name="BodyVel" site="imu"/>
        <gyro name="BodyGyro" site="imu"/>
        <framepos name="BodyPos" objtype="site" objname="imu"/>
        <framequat name="BodyQuat" objtype="site" objname="imu"/>
    </sensor>
</mujoco>