<?xml version="1.0" encoding="utf-8"?>
<!-- This URDF was automatically created by SolidWorks to URDF Exporter! Originally created by Stephen Brawner (brawner@gmail.com)  Commit Version: 1.6.0-4-g7f85cfe Build Version: 1.6.7995.38578 For more information, please see http://wiki.ros.org/sw_urdf_exporter -->
<robot name="humanoid_legged_description">
  <link name="dummy_link">
    </link>
  <link name="base_link">
    <inertial>
      <origin xyz="-0.1722 -0.00942 0.03461" rpy="0 0 0" />
      <mass value="5.55546" />
      <inertia ixx="0.02023" ixy="1e-05" ixz="0.00011" iyy="0.00815" iyz="0.00021" izz="0.02067" />
    </inertial>
    <!-- <visual>
      <origin xyz="0 0 0" rpy="0 0 0" />
      <geometry>
        <mesh filename="../meshes/LINK_BASE.STL" />
      </geometry>
      <material name="">
        <color rgba="0.75294 0.75294 0.75294 1" />
      </material>
    </visual> -->
    <collision>
      <origin xyz="0 0 0" rpy="0 0 0" />
      <geometry>
        <!-- <mesh filename="package://humanoid_legged_description/meshes/LINK_BASE.STL" /> -->
        <box size="0.2 0.3 0.3"/>
      </geometry>
    </collision>
  </link>

  <joint name="dummy_to_base_link" type="fixed">
    <parent link="dummy_link"/>
    <child link="base_link"/>
    <origin rpy="0 0 0" xyz="0 0 0"/>
  </joint>

  <!-- <joint name="DUMMY_JOINT_MAN_COM" type="fixed">
    <origin xyz="-0.246 0 0" rpy="0 0 0" />
    <parent link="LINK_BASE" />
    <child link="DUMMY_LINK_MAN_COM" />
  </joint>
  <link name="DUMMY_LINK_MAN_COM">
    <inertial>
      <origin xyz="0 0 0" rpy="0 0 0" />
      <mass value="70.0" />
      <inertia ixx="0.1" ixy="0" ixz="0" iyy="0.1" iyz="0" izz="0.1" />
    </inertial>
  </link> -->
<!-- 
  <link name="HUMAN_TORSO">
    <inertial>
      <origin xyz="0 0 0" rpy="0 0 0"/>
      <mass value="45.0"/>
      <inertia ixx="0.1" ixy="0" ixz="0" iyy="0.1" iyz="0" izz="0.1"/>
    </inertial>
  </link>

  <link name="HUMAN_THIGH_R">
    <inertial>
      <origin xyz="0 0 -0.2" rpy="1.5708 0 0"/>
      <mass value="5.0"/>
      <inertia ixx="0.02" ixy="0" ixz="0" iyy="0.02" iyz="0" izz="0.02"/>
    </inertial>
  </link>

  <link name="HUMAN_SHANK_R">
    <inertial>
      <origin xyz="0 0 -0.05" rpy="1.5708 0 0"/>
      <mass value="3.0"/>
      <inertia ixx="0.015" ixy="0" ixz="0" iyy="0.015" iyz="0" izz="0.015"/>
    </inertial>
  </link>

  <link name="HUMAN_THIGH_L">
    <inertial>
      <origin xyz="0 0 -0.2" rpy="1.5708 0 0"/>
      <mass value="5.0"/>
      <inertia ixx="0.02" ixy="0" ixz="0" iyy="0.02" iyz="0" izz="0.02"/>
    </inertial>
  </link>

  <link name="HUMAN_SHANK_L">
    <inertial>
      <origin xyz="0 0 -0.05" rpy="1.5708 0 0"/>
      <mass value="3.0"/>
      <inertia ixx="0.015" ixy="0" ixz="0" iyy="0.015" iyz="0" izz="0.015"/>
    </inertial>
  </link>



  <joint name="HUMAN_TORSO_TO_EXO" type="fixed">
    <origin xyz="-0.235 0 0.45" rpy="0 0 0"/>
    <parent link="base_link"/>
    <child link="HUMAN_TORSO"/>
  </joint>

  <joint name="HUMAN_THIGH_R_TO_EXO" type="fixed">
    <origin xyz="0.15 -0.2 0" rpy="0 0 0"/>
    <parent link="LINK_R_THIGH"/>
    <child link="HUMAN_THIGH_R"/>
  </joint>

  <joint name="HUMAN_SHANK_R_TO_EXO" type="fixed">
    <origin xyz="0.15 -0.1 0" rpy="0 0 0"/>
    <parent link="LINK_R_SHANK"/>
    <child link="HUMAN_SHANK_R"/>
  </joint>

  <joint name="HUMAN_THIGH_L_TO_EXO" type="fixed">
    <origin xyz="-0.15 -0.2 0" rpy="0 0 0"/>
    <parent link="LINK_L_THIGH"/>
    <child link="HUMAN_THIGH_L"/>
  </joint>

  <joint name="HUMAN_SHANK_L_TO_EXO" type="fixed">
    <origin xyz="-0.15 -0.1 0" rpy="0 0 0"/>
    <parent link="LINK_L_SHANK"/>
    <child link="HUMAN_SHANK_L"/>
  </joint> -->


  
  
  <link name="LINK_R_BASE">
    <inertial>
      <origin xyz="-0.15578 -0.11808 -0.01482" rpy="0 0 0" />
      <mass value="2.64278" />
      <inertia ixx="0.003" ixy="-0.00063" ixz="-0.00046" iyy="0.00376" iyz="0.00029" izz="0.00493" />
    </inertial>
    <!-- <visual>
      <origin xyz="0 0 0" rpy="0 0 0" />
      <geometry>
        <mesh filename="../meshes/LINK_R_BASE.STL" />
      </geometry>
      <material name="">
        <color rgba="0.75294 0.75294 0.75294 1" />
      </material>
    </visual> -->
    <collision>
      <origin xyz="0 0 0" rpy="0 0 0" />
      <geometry>
        <!-- <mesh filename="package://humanoid_legged_description/meshes/LINK_R_BASE.STL" /> -->
        <box size="0.2 0.3 0.3"/>
      </geometry>
    </collision>
  </link>
  <link name="LINK_R_HIP">
    <inertial>
      <origin xyz="0.1573 0.00247 0.00753" rpy="0 0 0" />
      <mass value="3.93858" />
      <inertia ixx="0.00404" ixy="4e-05" ixz="0.00037" iyy="0.00711" iyz="-1e-05" izz="0.00404" />
    </inertial>
    <!-- <visual>
      <origin xyz="0 0 0" rpy="0 0 0" />
      <geometry>
        <mesh filename="../meshes/LINK_R_HIP.STL" />
      </geometry>
      <material name="">
        <color rgba="0.75294 0.75294 0.75294 1" />
      </material>
    </visual> -->
    <collision>
      <origin xyz="0 0 0" rpy="0 0 0" />
      <geometry>
        <!-- <mesh filename="package://humanoid_legged_description/meshes/LINK_R_HIP.STL" /> -->
        <box size="0.2 0.3 0.3"/>
      </geometry>
    </collision>
  </link>
  <link name="LINK_R_THIGH">
    <inertial>
      <origin xyz="0.02583 -0.24821 -0.00792" rpy="0 0 0" />
      <mass value="3.57819" />
      <inertia ixx="0.00722" ixy="0.00023" ixz="1e-05" iyy="0.00309" iyz="0" izz="0.00598" />
    </inertial>
    <!-- <visual>
      <origin xyz="0 0 0" rpy="0 0 0" />
      <geometry>
        <mesh filename="../meshes/LINK_R_THIGH.STL" />
      </geometry>
      <material name="">
        <color rgba="0.75294 0.75294 0.75294 1" />
      </material>
    </visual> -->
    <collision>
      <origin xyz="0 0 0" rpy="0 0 0" />
      <geometry>
        <!-- <mesh filename="package://humanoid_legged_description/meshes/LINK_R_THIGH.STL" /> -->
        <box size="0.2 0.3 0.3"/>
      </geometry>
    </collision>
  </link>
  <link name="LINK_R_SHANK">
    <inertial>
      <origin xyz="0.12436 -0.11397 0.09477" rpy="0 0 0" />
      <mass value="2.52223" />
      <inertia ixx="0.00751" ixy="-7e-05" ixz="-0.00053" iyy="0.00225" iyz="-0.00032" izz="0.00788" />
    </inertial>
    <!-- <visual>
      <origin xyz="0 0 0" rpy="0 0 0" />
      <geometry>
        <mesh filename="../meshes/LINK_R_SHANK.STL" />
      </geometry>
      <material name="">
        <color rgba="0.75294 0.75294 0.75294 1" />
      </material>
    </visual> -->
    <collision>
      <origin xyz="0 0 0" rpy="0 0 0" />
      <geometry>
        <!-- <mesh filename="package://humanoid_legged_description/meshes/LINK_R_SHANK.STL" /> -->
        <box size="0.2 0.3 0.3"/>
      </geometry>
    </collision>
  </link>
  <link name="LINK_R_ANK">
    <inertial>
      <origin xyz="0 0.00012 -0.06408" rpy="0 0 0" />
      <mass value="0.55947" />
      <inertia ixx="0.00102" ixy="0" ixz="0" iyy="0.00286" iyz="0" izz="0.00202" />
    </inertial>
    <!-- <visual>
      <origin xyz="0 0 0" rpy="0 0 0" />
      <geometry>
        <mesh filename="../meshes/LINK_R_ANK.STL" />
      </geometry>
      <material name="">
        <color rgba="0.75294 0.75294 0.75294 1" />
      </material>
    </visual> -->
    <collision>
      <origin xyz="0 0 0" rpy="0 0 0" />
      <geometry>
        <!-- <mesh filename="package://humanoid_legged_description/meshes/LINK_R_ANK.STL" /> -->
        <box size="0.2 0.3 0.3"/>
      </geometry>
    </collision>
  </link>
  <link name="LINK_R_FOOT">
    <inertial>
      <origin xyz="0.08531 -0.1009 0.08681" rpy="0 0 0" />
      <mass value="4.0801" />
      <inertia ixx="0.02694" ixy="-9e-05" ixz="0.00014" iyy="0.03643" iyz="0.00025" izz="0.01075" />
    </inertial>
    <!-- <visual>
      <origin xyz="0 0 0" rpy="0 0 0" />
      <geometry>
        <mesh filename="../meshes/LINK_R_FOOT.STL" />
      </geometry>
      <material name="">
        <color rgba="0.75294 0.75294 0.75294 1" />
      </material>
    </visual> -->
    <collision>
      <origin xyz="0 0 0" rpy="0 0 0" />
      <geometry>
        <!-- <mesh filename="package://humanoid_legged_description/meshes/LINK_R_FOOT.STL" /> -->
        <box size="0.2 0.3 0.3"/>
      </geometry>
    </collision>
  </link>
  <link name="LINK_RR_DPIN">
    <inertial>
      <origin xyz="0 0 0" rpy="0 0 0" />
      <mass value="0.0457" />
      <inertia ixx="0" ixy="0" ixz="0" iyy="0" iyz="0" izz="0" />
    </inertial>
    <!-- <visual>
      <origin xyz="0 0 0" rpy="0 0 0" />
      <geometry>
        <mesh filename="../meshes/LINK_RR_DPIN.STL" />
      </geometry>
      <material name="">
        <color rgba="0.65098 0.61961 0.58824 1" />
      </material>
    </visual> -->
    <collision>
      <origin xyz="0 0 0" rpy="0 0 0" />
      <geometry>
        <!-- <mesh filename="package://humanoid_legged_description/meshes/LINK_RR_DPIN.STL" /> -->
        <box size="0.2 0.3 0.3"/>
      </geometry>
    </collision>
  </link>
  <link name="LINK_RR_SCREW">
    <inertial>
      <origin xyz="-0.00055 0 0.13102" rpy="0 0 0" />
      <mass value="0.44127" />
      <inertia ixx="0.00189" ixy="0" ixz="1e-05" iyy="0.00189" iyz="0" izz="2e-05" />
    </inertial>
    <!-- <visual>
      <origin xyz="0 0 0" rpy="0 0 0" />
      <geometry>
        <mesh filename="../meshes/LINK_RR_SCREW.STL" />
      </geometry>
      <material name="">
        <color rgba="0.75294 0.75294 0.75294 1" />
      </material>
    </visual> -->
    <collision>
      <origin xyz="0 0 0" rpy="0 0 0" />
      <geometry>
        <!-- <mesh filename="package://humanoid_legged_description/meshes/LINK_RR_SCREW.STL" /> -->
        <box size="0.2 0.3 0.3"/>
      </geometry>
    </collision>
  </link>
  <link name="LINK_RL_DPIN">
    <inertial>
      <origin xyz="0 0 0" rpy="0 0 0" />
      <mass value="0.0457" />
      <inertia ixx="0" ixy="0" ixz="0" iyy="0" iyz="0" izz="0" />
    </inertial>
    <!-- <visual>
      <origin xyz="0 0 0" rpy="0 0 0" />
      <geometry>
        <mesh filename="../meshes/LINK_RL_DPIN.STL" />
      </geometry>
      <material name="">
        <color rgba="0.65098 0.61961 0.58824 1" />
      </material>
    </visual> -->
    <collision>
      <origin xyz="0 0 0" rpy="0 0 0" />
      <geometry>
        <!-- <mesh filename="package://humanoid_legged_description/meshes/LINK_RL_DPIN.STL" /> -->
        <box size="0.2 0.3 0.3"/>
      </geometry>
    </collision>
  </link>
  <link name="LINK_RL_SCREW">
    <inertial>
      <origin xyz="0.00491 0 0.13092" rpy="0 0 0" />
      <mass value="0.44127" />
      <inertia ixx="0.00189" ixy="0" ixz="-7e-05" iyy="0.00189" iyz="0" izz="2e-05" />
    </inertial>
    <!-- <visual>
      <origin xyz="0 0 0" rpy="0 0 0" />
      <geometry>
        <mesh filename="../meshes/LINK_RL_SCREW.STL" />
      </geometry>
      <material name="">
        <color rgba="0.75294 0.75294 0.75294 1" />
      </material>
    </visual> -->
    <collision>
      <origin xyz="0 0 0" rpy="0 0 0" />
      <geometry>
        <!-- <mesh filename="package://humanoid_legged_description/meshes/LINK_RL_SCREW.STL" /> -->
        <box size="0.2 0.3 0.3"/>
      </geometry>
    </collision>
  </link>
  <link name="LINK_RR_UPIN">
    <inertial>
      <origin xyz="0 0 0" rpy="0 0 0" />
      <mass value="0.04441" />
      <inertia ixx="0" ixy="0" ixz="0" iyy="0" iyz="0" izz="0" />
    </inertial>
    <!-- <visual>
      <origin xyz="0 0 0" rpy="0 0 0" />
      <geometry>
        <mesh filename="../meshes/LINK_RR_UPIN.STL" />
      </geometry>
      <material name="">
        <color rgba="0.65098 0.61961 0.58824 1" />
      </material>
    </visual> -->
    <collision>
      <origin xyz="0 0 0" rpy="0 0 0" />
      <geometry>
        <!-- <mesh filename="package://humanoid_legged_description/meshes/LINK_RR_UPIN.STL" /> -->
        <box size="0.2 0.3 0.3"/>
      </geometry>
    </collision>
  </link>
  <link name="LINK_RR_ACTU">
    <inertial>
      <origin xyz="0.00021 -0.03662 -0.06019" rpy="0 0 0" />
      <mass value="1.3259" />
      <inertia ixx="0.00123" ixy="0" ixz="0" iyy="0.00122" iyz="0" izz="0.00066" />
    </inertial>
    <!-- <visual>
      <origin xyz="0 0 0" rpy="0 0 0" />
      <geometry>
        <mesh filename="../meshes/LINK_RR_ACTU.STL" />
      </geometry>
      <material name="">
        <color rgba="0.75294 0.75294 0.75294 1" />
      </material>
    </visual> -->
    <collision>
      <origin xyz="0 0 0" rpy="0 0 0" />
      <geometry>
        <!-- <mesh filename="package://humanoid_legged_description/meshes/LINK_RR_ACTU.STL" /> -->
        <box size="0.2 0.3 0.3"/>
      </geometry>
    </collision>
  </link>
  <link name="LINK_RL_UPIN">
    <inertial>
      <origin xyz="0 0 0" rpy="0 0 0" />
      <mass value="0.04441" />
      <inertia ixx="0" ixy="0" ixz="0" iyy="0" iyz="0" izz="0" />
    </inertial>
    <!-- <visual>
      <origin xyz="0 0 0" rpy="0 0 0" />
      <geometry>
        <mesh filename="../meshes/LINK_RL_UPIN.STL" />
      </geometry>
      <material name="">
        <color rgba="0.65098 0.61961 0.58824 1" />
      </material>
    </visual> -->
    <collision>
      <origin xyz="0 0 0" rpy="0 0 0" />
      <geometry>
        <!-- <mesh filename="package://humanoid_legged_description/meshes/LINK_RL_UPIN.STL" /> -->
        <box size="0.2 0.3 0.3"/>
      </geometry>
    </collision>
  </link>
  <link name="LINK_RL_ACTU">
    <inertial>
      <origin xyz="-0.00229 -0.03662 -0.06015" rpy="0 0 0" />
      <mass value="1.3259" />
      <inertia ixx="0.00123" ixy="0" ixz="-2e-05" iyy="0.00122" iyz="0" izz="0.00066" />
    </inertial>
    <!-- <visual>
      <origin xyz="0 0 0" rpy="0 0 0" />
      <geometry>
        <mesh filename="../meshes/LINK_RL_ACTU.STL" />
      </geometry>
      <material name="">
        <color rgba="0.75294 0.75294 0.75294 1" />
      </material>
    </visual> -->
    <collision>
      <origin xyz="0 0 0" rpy="0 0 0" />
      <geometry>
        <!-- <mesh filename="package://humanoid_legged_description/meshes/LINK_RL_ACTU.STL" /> -->
        <box size="0.2 0.3 0.3"/>
      </geometry>
    </collision>
  </link>
  <link name="LINK_R_ABD_ACTU">
    <inertial>
      <origin xyz="0.0384 -0.02898 -0.03467" rpy="0 0 0" />
      <mass value="1.82111" />
      <inertia ixx="0.00095" ixy="0" ixz="0" iyy="0.00119" iyz="0.00027" izz="0.00128" />
    </inertial>
    <!-- <visual>
      <origin xyz="0 0 0" rpy="0 0 0" />
      <geometry>
        <mesh filename="../meshes/LINK_R_ABD_ACTU.STL" />
      </geometry>
      <material name="">
        <color rgba="0.75294 0.75294 0.75294 1" />
      </material>
    </visual> -->
    <collision>
      <origin xyz="0 0 0" rpy="0 0 0" />
      <geometry>
        <!-- <mesh filename="package://humanoid_legged_description/meshes/LINK_R_ABD_ACTU.STL" /> -->
        <box size="0.2 0.3 0.3"/>
      </geometry>
    </collision>
  </link>
  <link name="LINK_L_BASE">
    <inertial>
      <origin xyz="-0.15582 0.11811 -0.01482" rpy="0 0 0" />
      <mass value="2.64202" />
      <inertia ixx="0.003" ixy="0.00063" ixz="-0.00046" iyy="0.00376" iyz="-0.00029" izz="0.00493" />
    </inertial>
    <!-- <visual>
      <origin xyz="0 0 0" rpy="0 0 0" />
      <geometry>
        <mesh filename="../meshes/LINK_L_BASE.STL" />
      </geometry>
      <material name="">
        <color rgba="0.75294 0.75294 0.75294 1" />
      </material>
    </visual> -->
    <collision>
      <origin xyz="0 0 0" rpy="0 0 0" />
      <geometry>
        <!-- <mesh filename="package://humanoid_legged_description/meshes/LINK_L_BASE.STL" /> -->
        <box size="0.2 0.3 0.3"/>
      </geometry>
    </collision>
  </link>
  <link name="LINK_L_HIP">
    <inertial>
      <origin xyz="0.1573 -0.00269 0.00753" rpy="0 0 0" />
      <mass value="3.93858" />
      <inertia ixx="0.00404" ixy="-4e-05" ixz="0.00037" iyy="0.00711" iyz="1e-05" izz="0.00404" />
    </inertial>
    <!-- <visual>
      <origin xyz="0 0 0" rpy="0 0 0" />
      <geometry>
        <mesh filename="../meshes/LINK_L_HIP.STL" />
      </geometry>
      <material name="">
        <color rgba="0.75294 0.75294 0.75294 1" />
      </material>
    </visual> -->
    <collision>
      <origin xyz="0 0 0" rpy="0 0 0" />
      <geometry>
        <!-- <mesh filename="package://humanoid_legged_description/meshes/LINK_L_HIP.STL" /> -->
        <box size="0.2 0.3 0.3"/>
      </geometry>
    </collision>
  </link>
  <link name="LINK_L_THIGH">
    <inertial>
      <origin xyz="-0.0215 -0.2549 -0.00789" rpy="0 0 0" />
      <mass value="3.04454" />
      <inertia ixx="0.00659" ixy="-0.0002" ixz="-1e-05" iyy="0.00287" iyz="0" izz="0.00537" />
    </inertial>
    <!-- <visual>
      <origin xyz="0 0 0" rpy="0 0 0" />
      <geometry>
        <mesh filename="../meshes/LINK_L_THIGH.STL" />
      </geometry>
      <material name="">
        <color rgba="0.75294 0.75294 0.75294 1" />
      </material>
    </visual> -->
    <collision>
      <origin xyz="0 0 0" rpy="0 0 0" />
      <geometry>
        <!-- <mesh filename="package://humanoid_legged_description/meshes/LINK_L_THIGH.STL" /> -->
        <box size="0.2 0.3 0.3"/>
      </geometry>
    </collision>
  </link>
  <link name="LINK_L_SHANK">
    <inertial>
      <origin xyz="-0.1241 -0.11379 0.09466" rpy="0 0 0" />
      <mass value="2.49032" />
      <inertia ixx="0.00751" ixy="7e-05" ixz="0.00053" iyy="0.00224" iyz="-0.00032" izz="0.00787" />
    </inertial>
    <!-- <visual>
      <origin xyz="0 0 0" rpy="0 0 0" />
      <geometry>
        <mesh filename="../meshes/LINK_L_SHANK.STL" />
      </geometry>
      <material name="">
        <color rgba="0.75294 0.75294 0.75294 1" />
      </material>
    </visual> -->
    <collision>
      <origin xyz="0 0 0" rpy="0 0 0" />
      <geometry>
        <!-- <mesh filename="package://humanoid_legged_description/meshes/LINK_L_SHANK.STL" /> -->
        <box size="0.2 0.3 0.3"/>
      </geometry>
    </collision>
  </link>
  <link name="LINK_L_ANK">
    <inertial>
      <origin xyz="0 0.00012 -0.06408" rpy="0 0 0" />
      <mass value="0.55947" />
      <inertia ixx="0.00102" ixy="0" ixz="0" iyy="0.00286" iyz="0" izz="0.00202" />
    </inertial>
    <!-- <visual>
      <origin xyz="0 0 0" rpy="0 0 0" />
      <geometry>
        <mesh filename="../meshes/LINK_L_ANK.STL" />
      </geometry>
      <material name="">
        <color rgba="0.75294 0.75294 0.75294 1" />
      </material>
    </visual> -->
    <collision>
      <origin xyz="0 0 0" rpy="0 0 0" />
      <geometry>
        <!-- <mesh filename="package://humanoid_legged_description/meshes/LINK_L_ANK.STL" /> -->
        <box size="0.2 0.3 0.3"/>
      </geometry>
    </collision>
  </link>
  <link name="LINK_L_FOOT">
    <inertial>
      <origin xyz="-0.08541 -0.09867 0.08624" rpy="0 0 0" />
      <mass value="3.99154" />
      <inertia ixx="0.0258" ixy="9e-05" ixz="-0.00014" iyy="0.03496" iyz="0.00025" izz="0.01043" />
    </inertial>
    <!-- <visual>
      <origin xyz="0 0 0" rpy="0 0 0" />
      <geometry>
        <mesh filename="../meshes/LINK_L_FOOT.STL" />
      </geometry>
      <material name="">
        <color rgba="0.75294 0.75294 0.75294 1" />
      </material>
    </visual> -->
    <collision>
      <origin xyz="0 0 0" rpy="0 0 0" />
      <geometry>
        <!-- <mesh filename="package://humanoid_legged_description/meshes/LINK_L_FOOT.STL" /> -->
        <box size="0.2 0.3 0.3"/>
      </geometry>
    </collision>
  </link>
  <link name="LINK_LR_DPIN">
    <inertial>
      <origin xyz="0 0 0" rpy="0 0 0" />
      <mass value="0.0457" />
      <inertia ixx="0" ixy="0" ixz="0" iyy="0" iyz="0" izz="0" />
    </inertial>
    <!-- <visual>
      <origin xyz="0 0 0" rpy="0 0 0" />
      <geometry>
        <mesh filename="../meshes/LINK_LR_DPIN.STL" />
      </geometry>
      <material name="">
        <color rgba="0.65098 0.61961 0.58824 1" />
      </material>
    </visual> -->
    <collision>
      <origin xyz="0 0 0" rpy="0 0 0" />
      <geometry>
        <!-- <mesh filename="package://humanoid_legged_description/meshes/LINK_LR_DPIN.STL" /> -->
        <box size="0.2 0.3 0.3"/>
      </geometry>
    </collision>
  </link>
  <link name="LINK_LR_SCREW">
    <inertial>
      <origin xyz="-0.00273 0 0.13099" rpy="0 0 0" />
      <mass value="0.44127" />
      <inertia ixx="0.00189" ixy="0" ixz="4e-05" iyy="0.00189" iyz="0" izz="2e-05" />
    </inertial>
    <!-- <visual>
      <origin xyz="0 0 0" rpy="0 0 0" />
      <geometry>
        <mesh filename="../meshes/LINK_LR_SCREW.STL" />
      </geometry>
      <material name="">
        <color rgba="0.75294 0.75294 0.75294 1" />
      </material>
    </visual> -->
    <collision>
      <origin xyz="0 0 0" rpy="0 0 0" />
      <geometry>
        <!-- <mesh filename="package://humanoid_legged_description/meshes/LINK_LR_SCREW.STL" /> -->
        <box size="0.2 0.3 0.3"/>
      </geometry>
    </collision>
  </link>
  <link name="LINK_LL_DPIN">
    <inertial>
      <origin xyz="0 0 0" rpy="0 0 0" />
      <mass value="0.0457" />
      <inertia ixx="0" ixy="0" ixz="0" iyy="0" iyz="0" izz="0" />
    </inertial>
    <!-- <visual>
      <origin xyz="0 0 0" rpy="0 0 0" />
      <geometry>
        <mesh filename="../meshes/LINK_LL_DPIN.STL" />
      </geometry>
      <material name="">
        <color rgba="0.65098 0.61961 0.58824 1" />
      </material>
    </visual> -->
    <collision>
      <origin xyz="0 0 0" rpy="0 0 0" />
      <geometry>
        <!-- <mesh filename="package://humanoid_legged_description/meshes/LINK_LL_DPIN.STL" /> -->
        <box size="0.2 0.3 0.3"/>
      </geometry>
    </collision>
  </link>
  <link name="LINK_LL_SCREW">
    <inertial>
      <origin xyz="0.00273 0 0.13099" rpy="0 0 0" />
      <mass value="0.44127" />
      <inertia ixx="0.00189" ixy="0" ixz="-4e-05" iyy="0.00189" iyz="0" izz="2e-05" />
    </inertial>
    <!-- <visual>
      <origin xyz="0 0 0" rpy="0 0 0" />
      <geometry>
        <mesh filename="../meshes/LINK_LL_SCREW.STL" />
      </geometry>
      <material name="">
        <color rgba="0.75294 0.75294 0.75294 1" />
      </material>
    </visual> -->
    <collision>
      <origin xyz="0 0 0" rpy="0 0 0" />
      <geometry>
        <!-- <mesh filename="package://humanoid_legged_description/meshes/LINK_LL_SCREW.STL" /> -->
        <box size="0.2 0.3 0.3"/>
      </geometry>
    </collision>
  </link>
  <link name="LINK_LR_UPIN">
    <inertial>
      <origin xyz="0 0 0" rpy="0 0 0" />
      <mass value="0.04441" />
      <inertia ixx="0" ixy="0" ixz="0" iyy="0" iyz="0" izz="0" />
    </inertial>
    <!-- <visual>
      <origin xyz="0 0 0" rpy="0 0 0" />
      <geometry>
        <mesh filename="../meshes/LINK_LR_UPIN.STL" />
      </geometry>
      <material name="">
        <color rgba="0.65098 0.61961 0.58824 1" />
      </material>
    </visual> -->
    <collision>
      <origin xyz="0 0 0" rpy="0 0 0" />
      <geometry>
        <!-- <mesh filename="package://humanoid_legged_description/meshes/LINK_LR_UPIN.STL" /> -->
        <box size="0.2 0.3 0.3"/>
      </geometry>
    </collision>
  </link>
  <link name="LINK_LR_ACTU">
    <inertial>
      <origin xyz="0.00122 0.03662 0.06018" rpy="0 0 0" />
      <mass value="1.3259" />
      <inertia ixx="0.00123" ixy="0" ixz="-1e-05" iyy="0.00122" iyz="0" izz="0.00066" />
    </inertial>
    <!-- <visual>
      <origin xyz="0 0 0" rpy="0 0 0" />
      <geometry>
        <mesh filename="../meshes/LINK_LR_ACTU.STL" />
      </geometry>
      <material name="">
        <color rgba="0.75294 0.75294 0.75294 1" />
      </material>
    </visual> -->
    <collision>
      <origin xyz="0 0 0" rpy="0 0 0" />
      <geometry>
        <!-- <mesh filename="package://humanoid_legged_description/meshes/LINK_LR_ACTU.STL" /> -->
        <box size="0.2 0.3 0.3"/>
      </geometry>
    </collision>
  </link>
  <link name="LINK_LL_UPIN">
    <inertial>
      <origin xyz="0 0 0" rpy="0 0 0" />
      <mass value="0.04441" />
      <inertia ixx="0" ixy="0" ixz="0" iyy="0" iyz="0" izz="0" />
    </inertial>
    <!-- <visual>
      <origin xyz="0 0 0" rpy="0 0 0" />
      <geometry>
        <mesh filename="../meshes/LINK_LL_UPIN.STL" />
      </geometry>
      <material name="">
        <color rgba="0.65098 0.61961 0.58824 1" />
      </material>
    </visual> -->
    <collision>
      <origin xyz="0 0 0" rpy="0 0 0" />
      <geometry>
        <!-- <mesh filename="package://humanoid_legged_description/meshes/LINK_LL_UPIN.STL" /> -->
        <box size="0.2 0.3 0.3"/>
      </geometry>
    </collision>
  </link>
  <link name="LINK_LL_ACTU">
    <inertial>
      <origin xyz="-0.00129 0.03662 0.06018" rpy="0 0 0" />
      <mass value="1.3259" />
      <inertia ixx="0.00123" ixy="0" ixz="1e-05" iyy="0.00122" iyz="0" izz="0.00066" />
    </inertial>
    <!-- <visual>
      <origin xyz="0 0 0" rpy="0 0 0" />
      <geometry>
        <mesh filename="../meshes/LINK_LL_ACTU.STL" />
      </geometry>
      <material name="">
        <color rgba="0.75294 0.75294 0.75294 1" />
      </material>
    </visual> -->
    <collision>
      <origin xyz="0 0 0" rpy="0 0 0" />
      <geometry>
        <!-- <mesh filename="package://humanoid_legged_description/meshes/LINK_LL_ACTU.STL" /> -->
        <box size="0.2 0.3 0.3"/>
      </geometry>
    </collision>
  </link>
  <link name="LINK_L_ABD_ACTU">
    <inertial>
      <origin xyz="0.03838 0.02875 -0.03454" rpy="0 0 0" />
      <mass value="1.81214" />
      <inertia ixx="0.00094" ixy="0" ixz="0" iyy="0.00118" iyz="-0.00027" izz="0.00128" />
    </inertial>
    <!-- <visual>
      <origin xyz="0 0 0" rpy="0 0 0" />
      <geometry>
        <mesh filename="../meshes/LINK_L_ABD_ACTU.STL" />
      </geometry>
      <material name="">
        <color rgba="0.75294 0.75294 0.75294 1" />
      </material>
    </visual> -->
    <collision>
      <origin xyz="0 0 0" rpy="0 0 0" />
      <geometry>
        <!-- <mesh filename="package://humanoid_legged_description/meshes/LINK_L_ABD_ACTU.STL" /> -->
        <box size="0.2 0.3 0.3"/>
      </geometry>
    </collision>
  </link>
  <link name="LINK_R_ABD_SCREW">
    <inertial>
      <origin xyz="-0.02112 -0.0446 -0.0533" rpy="0 0 0" />
      <mass value="0.2942" />
      <inertia ixx="0.00048" ixy="0" ixz="0" iyy="0.00029" iyz="-0.00023" izz="0.00021" />
    </inertial>
    <!-- <visual>
      <origin xyz="0 0 0" rpy="0 0 0" />
      <geometry>
        <mesh filename="../meshes/LINK_R_ABD_SCREW.STL" />
      </geometry>
      <material name="">
        <color rgba="0.75294 0.75294 0.75294 1" />
      </material>
    </visual> -->
    <collision>
      <origin xyz="0 0 0" rpy="0 0 0" />
      <geometry>
        <!-- <mesh filename="package://humanoid_legged_description/meshes/LINK_R_ABD_SCREW.STL" /> -->
        <box size="0.2 0.3 0.3"/>
      </geometry>
    </collision>
  </link>
  <link name="LINK_L_ABD_SCREW">
    <inertial>
      <origin xyz="-0.02112 0.0446 -0.0533" rpy="0 0 0" />
      <mass value="0.2942" />
      <inertia ixx="0.00048" ixy="0" ixz="0" iyy="0.00029" iyz="0.00023" izz="0.00021" />
    </inertial>
    <!-- <visual>
      <origin xyz="0 0 0" rpy="0 0 0" />
      <geometry>
        <mesh filename="../meshes/LINK_L_ABD_SCREW.STL" />
      </geometry>
      <material name="">
        <color rgba="0.75294 0.75294 0.75294 1" />
      </material>
    </visual> -->
    <collision>
      <origin xyz="0 0 0" rpy="0 0 0" />
      <geometry>
        <!-- <mesh filename="package://humanoid_legged_description/meshes/LINK_L_ABD_SCREW.STL" /> -->
        <box size="0.2 0.3 0.3"/>
      </geometry>
    </collision>
  </link>
  <joint name="leg_r1_joint" type="revolute">
    <origin xyz="0 -0.105 0" rpy="0 0 0" />
    <parent link="base_link" />
    <child link="LINK_R_BASE" />
    <axis xyz="-1 0 0" />
    <limit effort="0.0" lower="-0.17453" upper="0.2618" velocity="0.0"/>
  </joint>
  <joint name="leg_r2_joint" type="revolute">
    <origin xyz="-0.246 -0.155 0.0018" rpy="3.14159 1.5708 0" />
    <parent link="LINK_R_BASE" />
    <child link="LINK_R_HIP" />
    <axis xyz="1 0 0" />
    <limit effort="0.0" lower="-0.2618" upper="0.2618" velocity="0.0"/>
  </joint>
  <joint name="leg_r3_joint" type="revolute">
    <origin xyz="0.1908 0.036 0" rpy="-3.14159 0 -1.5708" />
    <parent link="LINK_R_HIP" />
    <child link="LINK_R_THIGH" />
    <axis xyz="-1 0 0" />
    <limit effort="0.0" lower="-0.52360" upper="1.884" velocity="0.0"/>
  </joint>
  <joint name="leg_r4_joint" type="revolute">
    <origin xyz="0.02624 -0.43062 -0.009" rpy="0 0 0" />
    <parent link="LINK_R_THIGH" />
    <child link="LINK_R_SHANK" />
    <axis xyz="1 0 0" />
    <limit effort="0.0" lower="0.004" upper="2.09440" velocity="0.0"/>
  </joint>
  <joint name="leg_r6_joint" type="revolute">
    <origin xyz="0.1445 -0.29452 0.12171" rpy="-0.69813 0 0" />
    <parent link="LINK_R_SHANK" />
    <child link="LINK_R_ANK" />
    <axis xyz="0 0 1" />
    <limit effort="0.0" lower="-0.1744" upper="0.2618" velocity="0.0"/>
  </joint>
  <joint name="leg_r5_joint" type="revolute">
    <origin xyz="-0.0885 0 -0.148" rpy="0.69813 0 0" />
    <parent link="LINK_R_ANK" />
    <child link="LINK_R_FOOT" />
    <axis xyz="1 0 0" />
    <limit effort="0.0" lower="-0.35" upper="0.52" velocity="0.0"/>
  </joint>

  <link name="r_foot_toe"/>
<joint name="r_foot_toe_joint" type="fixed">
  <origin xyz="0.08151 -0.140 0.23716" rpy="0 0 0"/>
  <parent link="LINK_R_FOOT"/>
  <child link="r_foot_toe"/>
</joint>

<link name="r_foot_heel"/>
<joint name="r_foot_heel_joint" type="fixed">
  <origin xyz="0.08151 -0.140 -0.08284" rpy="0 0 0"/>
  <parent link="LINK_R_FOOT"/>
  <child link="r_foot_heel"/>
</joint>


  <joint name="JOINT_RR_DPIN1" type="fixed">
    <origin xyz="0.036 -0.014 0.2299" rpy="-1.92378 0 0" />
    <parent link="LINK_R_FOOT" />
    <child link="LINK_RR_DPIN" />
    <axis xyz="-1 0 0" />
    <limit effort="0.0" lower="-3.14159265359" upper="3.14159265359" velocity="0.0"/>
  </joint>
  <joint name="JOINT_RR_DPIN2" type="fixed">
    <origin xyz="0 0 0" rpy="0 0 0" />
    <parent link="LINK_RR_DPIN" />
    <child link="LINK_RR_SCREW" />
    <axis xyz="0 1 0" />
    <limit effort="0.0" lower="-3.14159265359" upper="3.14159265359" velocity="0.0"/>
  </joint>
  <joint name="JOINT_RL_DPIN1" type="fixed">
    <origin xyz="0.141 -0.014 0.2301" rpy="-1.9286 0 0" />
    <parent link="LINK_R_FOOT" />
    <child link="LINK_RL_DPIN" />
    <axis xyz="1 0 0" />
    <limit effort="0.0" lower="-3.14159265359" upper="3.14159265359" velocity="0.0"/>
  </joint>
  <joint name="JOINT_RL_DPIN2" type="fixed">
    <origin xyz="0 0 0" rpy="0 0 0" />
    <parent link="LINK_RL_DPIN" />
    <child link="LINK_RL_SCREW" />
    <axis xyz="0 1 0" />
    <limit effort="0.0" lower="-3.14159265359" upper="3.14159265359" velocity="0.0"/>
  </joint>
  <joint name="JOINT_RR_UPIN1" type="fixed">
    <origin xyz="0.086 -0.14659 0.10362" rpy="-1.92339 0 0" />
    <parent link="LINK_R_SHANK" />
    <child link="LINK_RR_UPIN" />
    <axis xyz="-1 0 0" />
    <limit effort="0.0" lower="-3.14159265359" upper="3.14159265359" velocity="0.0"/>
  </joint>
  <joint name="JOINT_RR_UPIN2" type="fixed">
    <origin xyz="0 0 0" rpy="0 0 0" />
    <parent link="LINK_RR_UPIN" />
    <child link="LINK_RR_ACTU" />
    <axis xyz="0 1 0" />
    <limit effort="0.0" lower="-3.14159265359" upper="3.14159265359" velocity="0.0"/>
  </joint>
  <joint name="JOINT_RL_UPIN1" type="fixed">
    <origin xyz="0.203 -0.14659 0.10362" rpy="-1.92779 0 0" />
    <parent link="LINK_R_SHANK" />
    <child link="LINK_RL_UPIN" />
    <axis xyz="1 0 0" />
    <limit effort="0.0" lower="-3.14159265359" upper="3.14159265359" velocity="0.0"/>
  </joint>
  <joint name="JOINT_RL_UPIN2" type="fixed">
    <origin xyz="0 0 0" rpy="0 0 0" />
    <parent link="LINK_RL_UPIN" />
    <child link="LINK_RL_ACTU" />
    <axis xyz="0 0.99999 0.00439" />
    <limit effort="0.0" lower="-3.14159265359" upper="3.14159265359" velocity="0.0"/>
  </joint>
  <joint name="JOINT_R_ABD_ACTUSUB" type="fixed">
    <origin xyz="-0.089 -0.10864 0.05722" rpy="0 0 0" />
    <parent link="LINK_R_BASE" />
    <child link="LINK_R_ABD_ACTU" />
    <axis xyz="1 0 0" />
    <limit effort="0.0" lower="-3.14159265359" upper="3.14159265359" velocity="0.0"/>
  </joint>
  <joint name="leg_l1_joint" type="revolute">
    <origin xyz="0 0.105 0" rpy="0 0 0" />
    <parent link="base_link" />
    <child link="LINK_L_BASE" />
    <axis xyz="1 0 0" />
    <limit effort="0.0" lower="-0.17453" upper="0.2618" velocity="0.0"/>
  </joint>
  <joint name="leg_l2_joint" type="revolute">
    <origin xyz="-0.246 0.155 0.0018" rpy="3.14159 1.5708 0" />
    <parent link="LINK_L_BASE" />
    <child link="LINK_L_HIP" />
    <axis xyz="-1 0 0" />
    <limit effort="0.0" lower="-0.2618" upper="0.2618" velocity="0.0"/>
  </joint>
  <joint name="leg_l3_joint" type="revolute">
    <origin xyz="0.1908 -0.036 0" rpy="-3.14159 0 -1.5708" />
    <parent link="LINK_L_HIP" />
    <child link="LINK_L_THIGH" />
    <axis xyz="-1 0 0" />
    <limit effort="0.0" lower="-0.52360" upper="1.884" velocity="0.0"/>
  </joint>
  <joint name="leg_l4_joint" type="revolute">
    <origin xyz="-0.02624 -0.43062 -0.009" rpy="0 0 0" />
    <parent link="LINK_L_THIGH" />
    <child link="LINK_L_SHANK" />
    <axis xyz="1 0 0" />
    <limit effort="0.0" lower="0.004" upper="2.09440" velocity="0.0"/>
  </joint>
  <joint name="leg_l6_joint" type="revolute">
    <origin xyz="-0.1445 -0.29452 0.12171" rpy="-0.69813 0 0" />
    <parent link="LINK_L_SHANK" />
    <child link="LINK_L_ANK" />
    <axis xyz="0 0 -1" />
    <limit effort="0.0" lower="-0.1744" upper="0.2618" velocity="0.0"/>
  </joint>
  <joint name="leg_l5_joint" type="revolute">
    <origin xyz="0.0885 0 -0.148" rpy="0.69813 0 0" />
    <parent link="LINK_L_ANK" />
    <child link="LINK_L_FOOT" />
    <axis xyz="1 0 0" />
    <limit effort="0.0" lower="-0.35" upper="0.52" velocity="0.0"/>
  </joint>

  <link name="l_foot_toe"/>
<joint name="l_foot_toe_joint" type="fixed">
  <origin xyz="-0.08151 -0.140 0.23716" rpy="0 0 0"/>
  <parent link="LINK_L_FOOT"/>
  <child link="l_foot_toe"/>
</joint>

<link name="l_foot_heel"/>
<joint name="l_foot_heel_joint" type="fixed">
  <origin xyz="-0.08151 -0.140 -0.08284" rpy="0 0 0"/>
  <parent link="LINK_L_FOOT"/>
  <child link="l_foot_heel"/>
</joint>

  <joint name="JOINT_LR_DPIN1" type="fixed">
    <origin xyz="-0.141 -0.014 0.2299" rpy="-1.92536 0 0" />
    <parent link="LINK_L_FOOT" />
    <child link="LINK_LR_DPIN" />
    <axis xyz="-1 0 0" />
    <limit effort="0.0" lower="-3.14159265359" upper="3.14159265359" velocity="0.0"/>
  </joint>
  <joint name="JOINT_LR_DPIN2" type="fixed">
    <origin xyz="0 0 0" rpy="0 0 0" />
    <parent link="LINK_LR_DPIN" />
    <child link="LINK_LR_SCREW" />
    <axis xyz="0 1 0" />
    <limit effort="0.0" lower="-3.14159265359" upper="3.14159265359" velocity="0.0"/>
  </joint>
  <joint name="JOINT_LL_DPIN1" type="fixed">
    <origin xyz="-0.036 -0.014 0.2301" rpy="-1.92601 0 0" />
    <parent link="LINK_L_FOOT" />
    <child link="LINK_LL_DPIN" />
    <axis xyz="1 0 0" />
    <limit effort="0.0" lower="-3.14159265359" upper="3.14159265359" velocity="0.0"/>
  </joint>
  <joint name="JOINT_LL_DPIN2" type="fixed">
    <origin xyz="0 0 0" rpy="0 0 0" />
    <parent link="LINK_LL_DPIN" />
    <child link="LINK_LL_SCREW" />
    <axis xyz="0 1 0" />
    <limit effort="0.0" lower="-3.14159265359" upper="3.14159265359" velocity="0.0"/>
  </joint>
  <joint name="JOINT_LR_UPIN1" type="fixed">
    <origin xyz="-0.203 -0.14659 0.10362" rpy="1.21623 0 0" />
    <parent link="LINK_L_SHANK" />
    <child link="LINK_LR_UPIN" />
    <axis xyz="1 0 0" />
    <limit effort="0.0" lower="-3.14159265359" upper="3.14159265359" velocity="0.0"/>
  </joint>
  <joint name="JOINT_LR_UPIN2" type="fixed">
    <origin xyz="0 0 0" rpy="0 0 0" />
    <parent link="LINK_LR_UPIN" />
    <child link="LINK_LR_ACTU" />
    <axis xyz="0 -1 0" />
    <limit effort="0.0" lower="-3.14159265359" upper="3.14159265359" velocity="0.0"/>
  </joint>
  <joint name="JOINT_LL_UPIN1" type="fixed">
    <origin xyz="-0.086 -0.14659 0.10362" rpy="1.21558 0 0" />
    <parent link="LINK_L_SHANK" />
    <child link="LINK_LL_UPIN" />
    <axis xyz="1 0 0" />
    <limit effort="0.0" lower="-3.14159265359" upper="3.14159265359" velocity="0.0"/>
  </joint>
  <joint name="JOINT_LL_UPIN2" type="fixed">
    <origin xyz="0 0 0" rpy="0 0 0" />
    <parent link="LINK_LL_UPIN" />
    <child link="LINK_LL_ACTU" />
    <axis xyz="0 -1 0" />
    <limit effort="0.0" lower="-3.14159265359" upper="3.14159265359" velocity="0.0"/>
  </joint>
  <joint name="JOINT_L_ABD_ACTUSUB" type="fixed">
    <origin xyz="-0.089 0.109 0.057" rpy="0 0 0" />
    <parent link="LINK_L_BASE" />
    <child link="LINK_L_ABD_ACTU" />
    <axis xyz="1 0 0" />
    <limit effort="0.0" lower="-3.14159265359" upper="3.14159265359" velocity="0.0"/>
  </joint>
  <joint name="JOINT_R_ABD_SCREWSUB" type="fixed">
    <origin xyz="-0.027 -0.173 0.106" rpy="0 0 0" />
    <parent link="base_link" />
    <child link="LINK_R_ABD_SCREW" />
    <axis xyz="-1 0 0" />
    <limit effort="0.0" lower="-3.14159265359" upper="3.14159265359" velocity="0.0"/>
  </joint>
  <joint name="JOINT_L_ABD_SCREWSUB" type="fixed">
    <origin xyz="-0.027 0.173 0.106" rpy="0 0 0" />
    <parent link="base_link" />
    <child link="LINK_L_ABD_SCREW" />
    <axis xyz="-1 0 0" />
    <limit effort="0.0" lower="-3.14159265359" upper="3.14159265359" velocity="0.0"/>
  </joint>
</robot>